<?xml version="1.0" ?>
<robot name="robot_arm">

    <!-- Base link -->
    <link name="base_link" />

    <!-- Link 0 -->
    <link name="link0">
        <visual>
            <geometry>
                <box size="0.85 0.85 0.5"/>
            </geometry>
            <origin xyz="0 0 -0.4" rpy="0 0 0"/>
            <color rgba="1 1 0 1"/>
        </visual>
        
      
    </link>

    <!-- Joint 0 -->
    <joint name="joint0" type="fixed">
        <parent link="base_link"/>
        <child link="link0"/>
        <origin xyz="0 0 0.6" rpy="0 0 0"/>
    </joint>

    <!-- Link 1 -->
    <link name="link1">
      
        <visual>
            <geometry>
                <cylinder length="0.05" radius="0.25"/>
            </geometry>
            <origin xyz="0 0 -0.123" rpy="0 0 0"/>
            <color rgba="0 0 1 1"/>
        </visual>  
        
        <visual>
            <geometry>
                <box size="0.3 0.3 1"/>
            </geometry>
            <origin xyz="0 0.2 0.4" rpy="0 0 0"/>
            <color rgba="1 1 0 1"/>
        </visual>
        
        <visual>
            <geometry>
                <box size="0.3 0.5 0.3"/>
            </geometry>
            <origin xyz="0 0.6 0.5" rpy="0 0 0"/>
            <color rgba="1 1 0 1"/>
        </visual>

        <inertial>
            <origin xyz="0 0 0" rpy="0 0 0"/>
            <mass value="1"/> 
            <inertia ixx="0.001" ixy="0" ixz="0" iyy="0.001" iyz="0" izz="0.001"/>
        </inertial>
    </link>

    <!-- Joint 1 -->
    <joint name="joint1" type="revolute">
        <parent link="link0"/>
        <child link="link1"/>
        <origin xyz="0 0 0" rpy="0 0 0"/>
        <axis xyz="0 0 1"/>
        <limit lower="-3.0" upper="3" effort="300" velocity="0.7"/>
    </joint>

    <!-- Link 2 -->
    <link name="link2">
        <visual>
            <geometry>
                <box size="0.3 0.7 0.2"/>
            </geometry>
            <origin xyz="0 0 0" rpy="0 0 0"/>
            <color rgba="0 0 1 1"/>
            <inertia ixx="0.001" ixy="0" ixz="0" iyy="0.001" iyz="0" izz="0.001"/>
        </visual>
        
        <visual>
            <geometry>
                <box size="0.3 0.1 0.3"/>
            </geometry>
            <origin xyz="0 0.4 -0.05" rpy="0 0 0"/>
            <color rgba="1 1 0 1"/>
        </visual>
        
        <visual>
            <geometry>
                <box size="0.3 0.2 0.1"/>
            </geometry>
            <origin xyz="0 0.55 -0.15" rpy="0 0 0"/>
            <color rgba="1 1 0 1"/>
        </visual>
    </link>

    <!-- Joint 2 -->
    <joint name="joint2" type="revolute">
        <parent link="link1"/>
        <child link="link2"/>
        <origin xyz="0 0.8 0.75" rpy="0 0 0"/>
        <axis xyz="0 0 1"/>
        <limit lower="-1.5" upper="1.5" effort="200" velocity="2.0"/>
    </joint>

</robot>